Workbook

Sheet Дилеры_Август
A1: __EMPTY | B1: Время закрытия | C1: Deal_ID | D1: Идентификатор компании | E1: Название стадии | F1: Contact_ID | G1: client_id | H1: Название компании | I1: ИНН | J1: КВ. ИИ | K1: отчеты | L1: комментарий | N1: Цена | O1: КВ. Авто | P1: Номер ДКП | Q1: Дата ДКП | R1: brand | S1: model | T1: TYPE | U1: VIN | V1: Цена | W1: КВ. Авто | X1: Название товара | Y1: CITY | Z1: YEAR | AA1: Error | AB1: Ссылка на сделку
A2: 1391 | B2: 46238 | C2: 507548 | D2: 113190 | E2: Закрыто и реализованно | F2: 489446 | G2: 4733196 | H2: Online ГК Башавтоком, ООО "СТРОЙМОСТИНВЕСТ" | I2: 245013286 | J2: 28600 | K2: да | L2: ии не проверил | N2: 1430000 | O2: 28600 | P2: СМ000002442 | Q2: 46238 | R2: Lada (ВАЗ) | S2: Niva | T2: Новое | U2: XTA212310T0985466 | V2: 1430000 | W2: 28600 | X2: Lada (ВАЗ) Niva XTA212310T0985466 | Y2: Стерлитамак | Z2: 2026 | AA2: FALSE | AB2: <a href="https://sberauto.bitrix24.ru/crm/deal/details/507548/"target="_blank">Ссылка</a>
A3: 1579 | B3: 46238 | C3: 503526 | D3: 1956 | E3: Закрыто и реализованно | F3: 489446 | G3: 4733196 | H3: ГК Башавтоком, ООО "СТРОЙМОСТИНВЕСТ" | I3: 245013286 | L3: дубль сделки. | N3: 1430000 | O3: 28600 | P3: СМ000002442 | Q3: 46238 | R3: Lada (ВАЗ) | S3: Niva | T3: Новое | U3: XTA212310T0985466 | V3: 1430000 | W3: 28600 | X3: Lada (ВАЗ) Niva XTA212310T0985466 | Y3: Стерлитамак | Z3: 2026 | AA3: FALSE | AB3: <a href="https://sberauto.bitrix24.ru/crm/deal/details/503526/"target="_blank">Ссылка</a>
A4: 33 | B4: 46265 | C4: 535350 | D4: 113078 | E4: Закрыто и реализованно | F4: 510280 | G4: 4953612 | H4: ООО "МС МОТОРС ЗУБОВО" ONLINE | I4: 245961925 | J4: 49200 | K4: да | L4: ии не проверил | N4: 2460000 | O4: 49200 | P4: 26/08-46/AM | Q4: 46261 | R4: Jetour | S4: X70Plus | T4: Новое | U4: EC37LUSM6TC006527 | V4: 2460000 | W4: 49200 | X4: Jetour X70Plus EC37LUSM6TC006527 | Y4: Уфа | Z4: 2026 | AA4: FALSE | AB4: <a href="https://sberauto.bitrix24.ru/crm/deal/details/535350/"target="_blank">Ссылка</a>
A5: 1277 | B5: 46241 | C5: 509914 | D5: 113078 | E5: Закрыто и реализованно | F5: 494376 | G5: 5010914 | H5: ООО "МС МОТОРС ЗУБОВО" ONLINE | I5: 245961925 | J5: 48000 | K5: да | L5: ии не проверил | N5: 2400000 | O5: 48000 | P5: 26/08-07/AM | Q5: 46239 | R5: JETOUR | S5: DASHING | T5: Новое | U5: EC3DLUFD7TC013063 | V5: 2400000 | W5: 48000 | X5: JETOUR DASHING EC3DLUFD7TC013063 | Y5: Уфа | Z5: 2026 | AA5: FALSE | AB5: <a href="https://sberauto.bitrix24.ru/crm/deal/details/509914/"target="_blank">Ссылка</a>
A6: 1063 | B6: 46250 | C6: 514374 | D6: 76632 | E6: Закрыто и реализованно | F6: 497630 | G6: 5047174 | H6: ONLINE Динамика (ООО "ДИНАМИКА") | I6: 263009243 | J6: 32385 | K6: да | L6: ии не проверил | N6: 2159000 | O6: 32385 | P6: ЗА000004866 | Q6: 46246 | R6: JETOUR | S6: DASHING | T6: Новое | U6: EC3DCUFD5TC016057 | V6: 2159000 | W6: 32385 | X6: JETOUR DASHING EC3DCUFD5TC016057 | Y6: Архангельск | Z6: 2026 | AA6: FALSE | AB6: <a href="https://sberauto.bitrix24.ru/crm/deal/details/514374/"target="_blank">Ссылка</a>
A7: 480 | B7: 46260 | C7: 528212 | D7: 113516 | E7: Закрыто и реализованно | F7: 505728 | G7: 1354944 | H7: ООО "УРАЛ-МОТОРС" ONLINE | I7: 268068757 | J7: 74000 | K7: да | N7: 3700000 | O7: 74000 | P7: 2000 | Q7: 46259 | R7: Gac | S7: GS4 | T7: Новое | U7: LMGAE3G80T1004612 | V7: 3700000 | W7: 74000 | X7: Gac GS4 LMGAE3G80T1004612 | Y7: Стерлитамак | Z7: 2026 | AA7: FALSE | AB7: <a href="https://sberauto.bitrix24.ru/crm/deal/details/528212/"target="_blank">Ссылка</a>
A8: 1568 | B8: 46238 | C8: 505868 | D8: 113146 | E8: Закрыто и реализованно | F8: 491196 | G8: 4967624 | H8: Online ДАКТОР УФА СЕЛЬСКАЯ | I8: 276971419 | K8: да | L8: ии не проверил | N8: 2020900 | O8: 40418 | P8: УС000000434 | Q8: 46237 | R8: JETOUR | S8: DASHING | T8: Новое | U8: EC3DLUFD1TC012961 | V8: 2020900 | W8: 40418 | X8: JETOUR DASHING EC3DLUFD1TC012961 | Y8: Уфа | Z8: 2026 | AA8: FALSE | AB8: <a href="https://sberauto.bitrix24.ru/crm/deal/details/505868/"target="_blank">Ссылка</a>
A9: 180 | B9: 46264 | C9: 534038 | D9: 79732 | E9: Закрыто и реализованно | F9: 503164 | G9: 5093745 | H9: ONLINE Башавтоком (ООО "БАШАВТОКОМ-В") | I9: 278105341 | K9: да | L9: ии не проверил | N9: 1225000 | O9: 18375 | P9: B0000002711 | Q9: 46262 | R9: LADA | S9: GRANTA | T9: Новое | U9: ХТА219440V0324759 | V9: 1225000 | W9: 18375 | X9: Lada Granta ХТА219440V0324759 | Y9: Стерлитамак | Z9: 2026 | AA9: FALSE | AB9: <a href="https://sberauto.bitrix24.ru/crm/deal/details/534038/"target="_blank">Ссылка</a>
A10: 182 | B10: 46264 | C10: 534010 | D10: 79732 | E10: Закрыто и реализованно | F10: 503386 | G10: 5094393 | H10: ONLINE Башавтоком (ООО "БАШАВТОКОМ-В") | I10: 278105341 | K10: да | L10: ии не проверил | N10: 1121000 | O10: 16815 | P10: B0000002793 | Q10: 46262 | R10: LADA | S10: GRANTA | T10: Новое | U10: ХТА219040T1268071 | V10: 1121000 | W10: 16815 | X10: Lada Granta ХТА219040T1268071 | Y10: Стерлитамак | Z10: 2026 | AA10: FALSE | AB10: <a href="https://sberauto.bitrix24.ru/crm/deal/details/534010/"target="_blank">Ссылка</a>
A11: 372 | B11: 46260 | C11: 529958 | D11: 79732 | E11: Закрыто и реализованно | F11: 506378 | G11: 5120595 | H11: ONLINE Башавтоком (ООО "БАШАВТОКОМ-В") | I11: 278105341 | K11: да | L11: ии не проверил | N11: 1088000 | O11: 16320 | P11: B0000002772 | Q11: 46260 | R11: LADA | S11: GRANTA | T11: Новое | U11: XTA219040V1276059 | V11: 1088000 | W11: 16320 | X11: LADA GRANTA XTA219040V1276059 | Y11: Стерлитамак | Z11: 2026 | AA11: FALSE | AB11: <a href="https://sberauto.bitrix24.ru/crm/deal/details/529958/"target="_blank">Ссылка</a>
A12: 392 | B12: 46260 | C12: 529690 | D12: 79732 | E12: Закрыто и реализованно | F12: 505776 | G12: 5114557 | H12: ONLINE Башавтоком (ООО "БАШАВТОКОМ-В") | I12: 278105341 | K12: да | L12: ии не проверил | N12: 1654000 | O12: 24810 | P12: B0000002754 | Q12: 46259 | R12: LADA | S12: GRANTA | T12: Новое | U12: ХТА219040V1276057 | V12: 1654000 | W12: 24810 | X12: LADA GRANTA ХТА219040V1276057 | Y12: Стерлитамак | Z12: 2026 | AA12: FALSE | AB12: <a href="https://sberauto.bitrix24.ru/crm/deal/details/529690/"target="_blank">Ссылка</a>
A13: 494 | B13: 46258 | C13: 528042 | D13: 79732 | E13: Закрыто и реализованно | F13: 504390 | G13: 5104689 | H13: ONLINE Башавтоком (ООО "БАШАВТОКОМ-В") | I13: 278105341 | K13: да | L13: ии не проверил | N13: 1226000 | O13: 18390 | P13: B0000002734 | Q13: 46257 | R13: Lada | S13: Granta Cross | T13: Новое | U13: ХТА219470V0324758 | V13: 1226000 | W13: 18390 | X13: Lada Granta Cross ХТА219470V0324758 | Y13: Стерлитамак | Z13: 2026 | AA13: FALSE | AB13: <a href="https://sberauto.bitrix24.ru/crm/deal/details/528042/"target="_blank">Ссылка</a>
A14: 629 | B14: 46255 | C14: 526118 | D14: 79732 | E14: Закрыто и реализованно | F14: 503728 | G14: 5098167 | H14: ONLINE Башавтоком (ООО "БАШАВТОКОМ-В") | I14: 278105341 | K14: да | L14: ии не проверил | N14: 1189000 | O14: 17835 | P14: B0000002707 | Q14: 46255 | R14: LADA | S14: GRANTA | T14: Новое | U14: ХТА219440V0323249 | V14: 1189000 | W14: 17835 | X14: LADA GRANTA ХТА219440V0323249 | Y14: Стерлитамак | Z14: 2026 | AA14: FALSE | AB14: <a href="https://sberauto.bitrix24.ru/crm/deal/details/526118/"target="_blank">Ссылка</a>
A15: 713 | B15: 46255 | C15: 524852 | D15: 79732 | E15: Закрыто и реализованно | F15: 502676 | G15: 5088606 | H15: ONLINE Башавтоком (ООО "БАШАВТОКОМ-В") | I15: 278105341 | K15: да | L15: ии не проверил | N15: 1198000 | O15: 17970 | P15: B0000002695 | Q15: 46254 | R15: LADA | S15: GRANTA | T15: Новое | U15: XTA219470V0323264 | V15: 1198000 | W15: 17970 | X15: LADA Granta XTA219470V0323264 | Y15: Стерлитамак | Z15: 2026 | AA15: FALSE | AB15: <a href="https://sberauto.bitrix24.ru/crm/deal/details/524852/"target="_blank">Ссылка</a>
A16: 803 | B16: 46252 | C16: 523192 | D16: 79732 | E16: Закрыто и реализованно | F16: 501182 | G16: 5077481 | H16: ONLINE Башавтоком (ООО "БАШАВТОКОМ-В") | I16: 278105341 | K16: да | L16: ии не проверил | N16: 1096000 | O16: 16440 | P16: B0000002659 | Q16: 46252 | R16: LADA | S16: GRANTA | T16: Новое | U16: ХТА219040V1275881 | V16: 1096000 | W16: 16440 | X16: LADA GRANTA ХТА219040V1275881 | Y16: Стерлитамак | Z16: 2026 | AA16: FALSE | AB16: <a href="https://sberauto.bitrix24.ru/crm/deal/details/523192/"target="_blank">Ссылка</a>
A17: 875 | B17: 46250 | C17: 518180 | D17: 79732 | E17: Закрыто и реализованно | F17: 500418 | G17: 5070713 | H17: ONLINE Башавтоком (ООО "БАШАВТОКОМ-В") | I17: 278105341 | K17: да | L17: ии не проверил | N17: 1832000 | O17: 27480 | P17: B0000002633 | Q17: 46250 | R17: LADA | S17: Vesta | T17: Новое | U17: XTAGFL110V1060519 | V17: 1832000 | W17: 27480 | X17: Lada Vesta XTAGFL110V1060519 | Y17: Уфа | Z17: 2026 | AA17: FALSE | AB17: <a href="https://sberauto.bitrix24.ru/crm/deal/details/518180/"target="_blank">Ссылка</a>
A18: 884 | B18: 46250 | C18: 518072 | D18: 79732 | E18: Закрыто и реализованно | F18: 497164 | G18: 5041658 | H18: ONLINE Башавтоком (ООО "БАШАВТОКОМ-В") | I18: 278105341 | K18: да | L18: ии не проверил | N18: 1789000 | O18: 26835 | P18: В0000002539 | Q18: 46248 | R18: LADA | S18: Niva Travel | T18: Новое | U18: XTA212310T1000782 | V18: 1789000 | W18: 26835 | X18: LADA Niva Travel XTA212310T1000782 | Y18: Стерлитамак | Z18: 2026 | AA18: FALSE | AB18: <a href="https://sberauto.bitrix24.ru/crm/deal/details/518072/"target="_blank">Ссылка</a>
A19: 936 | B19: 46249 | C19: 517190 | D19: 79732 | E19: Закрыто и реализованно | F19: 499130 | G19: 5059112 | H19: ONLINE Башавтоком (ООО "БАШАВТОКОМ-В") | I19: 278105341 | K19: да | L19: ии не проверил | N19: 1810000 | O19: 27150 | P19: B0000002585 | Q19: 46248 | R19: LADA | S19: Niva | T19: Новое | U19: XTA212310V1005472 | V19: 1810000 | W19: 27150 | X19: Lada Niva XTA212310V1005472 | Y19: Стерлитамак | Z19: 2026 | AA19: FALSE | AB19: <a href="https://sberauto.bitrix24.ru/crm/deal/details/517190/"target="_blank">Ссылка</a>
... A23: 892 | B23: 46252 | C23: 517968 | D23: 82164 | E23: Закрыто и реализованно | F23: 500490 | G23: 2718950 | H23: ONLINE CHERY Динамика (ООО "ДИНАМИКА АРХАНГЕЛЬСК РР") | I23: 1101096766 | K23: да | L23: ии не проверил | N23: 2100000 | O23: 21000 | P23: ЗА000004994 | Q23: 46251 | R23: JETOUR | S23: DASHING | T23: Новое | U23: EC3DCUFD8TC010687 | V23: 2100000 | W23: 21000 | X23: Jetour Dashing EC3DCUFD8TC010687 | Y23: Архангельск | Z23: 2026 | AA23: FALSE | AB23: <a href="https://sberauto.bitrix24.ru/crm/deal/details/517968/"target="_blank">Ссылка</a>
A24: 262 | B24: 46262 | C24: 532232 | D24: 113584 | E24: Закрыто и реализованно | F24: 508644 | G24: 5142873 | H24: АЛЕКСМОТОРС ONLINE | I24: 1101126185 | J24: 75000 | K24: да | N24: 3750000 | O24: 75000 | P24: ДФ 0079/2026 | Q24: 46262 | R24: JETOUR | S24: Т1 | T24: Новое | U24: LVTDD24B5TDB86498 | V24: 3750000 | W24: 75000 | X24: Jetour T1 LVTDD24B5TDB86498 | Y24: Сыктывкар | Z24: 2026 | AA24: FALSE | AB24: <a href="https://sberauto.bitrix24.ru/crm/deal/details/532232/"target="_blank">Ссылка</a>
A25: 11 | B25: 46265 | C25: 535452 | D25: 112880 | E25: Закрыто и реализованно | F25: 511438 | G25: 5166407 | H25: Online ООО "ЛЕОН" | I25: 1207901941 | J25: 51000 | K25: да | N25: 2550000 | O25: 51000 | P25: ДТ-72 | Q25: 46265 | R25: Soueast | S25: S06 | T25: Новое | U25: EC3DCUGA5TC000896 | V25: 2550000 | W25: 51000 | X25: Soueast S06 EC3DCUGA5TC000896 | Y25: РЕСПУБЛИКА МАРИЙ ЭЛ | Z25: 2026 | AA25: FALSE | AB25: <a href="https://sberauto.bitrix24.ru/crm/deal/details/535452/"target="_blank">Ссылка</a>
A26: 181 | B26: 46264 | C26: 534018 | D26: 112880 | E26: Закрыто и реализованно | F26: 501946 | G26: 4893504 | H26: Online ООО "ЛЕОН" | I26: 1207901941 | J26: 73400 | K26: да | N26: 3670000 | O26: 73400 | P26: ДТ-61 | Q26: 46263 | R26: JETOUR | S26: Т1 | T26: Новое | U26: LVTDD24B4TDB99632 | V26: 3670000 | W26: 73400 | X26: JETOUR T1 LVTDD24B4TDB99632 | Y26: Медведево | Z26: 2026 | AA26: FALSE | AB26: <a href="https://sberauto.bitrix24.ru/crm/deal/details/534018/"target="_blank">Ссылка</a>
A27: 1525 | B27: 46237 | C27: 506246 | D27: 112880 | E27: Закрыто и реализованно | F27: 489892 | G27: 4970808 | H27: Online ООО "ЛЕОН" | I27: 1207901941 | J27: 42600 | K27: да | N27: 2130000 | O27: 42600 | P27: ДТ-46 | Q27: 46234 | R27: JETOUR | S27: X70 PLUS | T27: Новое | U27: EC37CUSM5TC005868 | V27: 2130000 | W27: 42600 | X27: JETOUR X70 PLUS EC37CUSM5TC005868 | Y27: Медведево | Z27: 2026 | AA27: FALSE | AB27: <a href="https://sberauto.bitrix24.ru/crm/deal/details/506246/"target="_blank">Ссылка</a>
A28: 1528 | B28: 46237 | C28: 506206 | D28: 112880 | E28: Закрыто и реализованно | F28: 491448 | G28: 4708919 | H28: Online ООО "ЛЕОН" | I28: 1207901941 | J28: 45400 | K28: да | N28: 2270000 | O28: 45400 | P28: ДТ-45 | Q28: 46234 | R28: JETOUR | S28: X70 PLUS | T28: Новое | U28: EC37LUSM6TC006575 | V28: 2270000 | W28: 45400 | X28: JETOUR X70 PLUS EC37LUSM6TC006575 | Y28: МЕДВЕДЕВО | Z28: 2026 | AA28: FALSE | AB28: <a href="https://sberauto.bitrix24.ru/crm/deal/details/506206/"target="_blank">Ссылка</a>
A29: 1594 | B29: 46238 | C29: 502336 | D29: 111882 | E29: Закрыто и реализованно | F29: 488506 | G29: 4957664 | H29: ООО "КМ-АВТО САРАНСК-2" ONLINE | I29: 1300005883 | J29: 57000 | K29: да | N29: 2850000 | O29: 57000 | P29: М000000068 | Q29: 46235 | R29: Solaris | S29: KRX | T29: Новое | U29: Z94C351BBSR196070 | V29: 2850000 | W29: 57000 | X29: Solaris KRX Z94C351BBSR196070 | Y29: Саранск | Z29: 2026 | AA29: FALSE | AB29: <a href="https://sberauto.bitrix24.ru/crm/deal/details/502336/"target="_blank">Ссылка</a>
A30: 1673 | B30: 46246 | C30: 483622 | D30: 111882 | E30: Закрыто и реализованно | F30: 475000 | G30: 4830365 | H30: ООО "КМ-АВТО САРАНСК-2" ONLINE | I30: 1300005883 | J30: 51000 | K30: да | N30: 2550000 | O30: 51000 | P30: М000000061 | Q30: 46212 | R30: Solaris | S30: KRX | T30: Новое | U30: Z94C251BBSR200339 | V30: 2550000 | W30: 51000 | X30: Solaris KRX Z94C251BBSR200339 | Y30: Саранск | Z30: 2025 | AA30: FALSE | AB30: <a href="https://sberauto.bitrix24.ru/crm/deal/details/483622/"target="_blank">Ссылка</a>
A31: 147 | B31: 46264 | C31: 534388 | D31: 112710 | E31: Закрыто и реализованно | F31: 473224 | G31: 1479681 | H31: ООО "АРМАДА-АВТО" online | I31: 1615009225 | J31: 49200 | K31: да | N31: 2460000 | O31: 49200 | P31: AA00000983 | Q31: 46263 | R31: JETOUR | S31: X70+ | T31: Новое | U31: EC37LUSM9TC007350 | V31: 2460000 | W31: 49200 | X31: JETOUR X70+ EC37LUSM9TC007350 | Y31: Нижнекамск | Z31: 2026 | AA31: FALSE | AB31: <a href="https://sberauto.bitrix24.ru/crm/deal/details/534388/"target="_blank">Ссылка</a>
A32: 1337 | B32: 46239 | C32: 508702 | D32: 112710 | E32: Закрыто и реализованно | F32: 261898 | G32: 2908721 | H32: ООО "АРМАДА-АВТО" online | I32: 1615009225 | J32: 57456 | K32: да | N32: 2872800 | O32: 57456 | P32: АА00000857 | Q32: 46239 | R32: SOLARIS | S32: HC | T32: Новое | U32: Z94PF815BSR065403 | V32: 2872800 | W32: 57456 | X32: Solaris HC Z94PF815BSR065403 | Y32: Нижнекамск | Z32: 2025 | AA32: FALSE | AB32: <a href="https://sberauto.bitrix24.ru/crm/deal/details/508702/"target="_blank">Ссылка</a>
A33: 1654 | B33: 46238 | C33: 490494 | D33: 108228 | E33: Закрыто и реализованно | F33: 479820 | G33: 4878511 | H33: ONLINE ГК Диалог \ ООО Диалог Авто | I33: 1644062657 | J33: 42600 | K33: да | N33: 2130000 | O33: 42600 | P33: 26/07/17-02 | Q33: 46220 | R33: Jetour | S33: X70 + | T33: Новое | U33: EC37CUSM4SC004659 | V33: 2130000 | W33: 42600 | X33: Jetour X70 + EC37CUSM4SC004659 | Y33: Казань | Z33: 2026 | AA33: FALSE | AB33: <a href="https://sberauto.bitrix24.ru/crm/deal/details/490494/"target="_blank">Ссылка</a>
A34: 1266 | B34: 46248 | C34: 510012 | D34: 107326 | E34: Закрыто и реализованно | F34: 494476 | G34: 4777908 | H34: ONLINE ООО "ДИАЛОГ АВТО" | I34: 1644062657 | J34: 40000 | K34: да | N34: 2000000 | O34: 40000 | P34: 26/08/07-01 | Q34: 46241 | R34: Jetour | S34: Dashing | T34: Новое | U34: EC3DCUFD8TC014626 | V34: 2000000 | W34: 40000 | X34: Jetour Dashing EC3DCUFD8TC014626 | Y34: Казань | Z34: 2026 | AA34: FALSE | AB34: <a href="https://sberauto.bitrix24.ru/crm/deal/details/510012/"target="_blank">Ссылка</a>
A35: 20 | B35: 46265 | C35: 535394 | D35: 107326 | E35: Закрыто и реализованно | F35: 511386 | G35: 5094107 | H35: ONLINE ООО "ДИАЛОГ АВТО" | I35: 1644062657 | J35: 10800 | K35: да | N35: 540000 | O35: 10800 | P35: 26/08/31-05 | Q35: 46265 | R35: Mini | S35: One | T35: Б/У | U35: WMWME31090TU04249 | V35: 540000 | W35: 10800 | X35: Mini One WMWME31090TU04249 | Y35: Альметьевск | Z35: 2007 | AA35: FALSE | AB35: <a href="https://sberauto.bitrix24.ru/crm/deal/details/535394/"target="_blank">Ссылка</a>
... A69: 1518 | B69: 46237 | C69: 506282 | D69: 102862 | E69: Закрыто и реализованно | F69: 491510 | G69: 4979253 | H69: ONLINE ДИАЛОГ А | I69: 1649021206 | J69: 39400 | K69: да | N69: 1970000 | O69: 39400 | P69: 26/08/01-01 | Q69: 46235 | R69: JETOUR | S69: DASHING | T69: Новое | U69: EC3DCUFDXTC014546 | V69: 1970000 | W69: 39400 | X69: JETOUR DASHING EC3DCUFDXTC014546 | Y69: Набережные Челны | Z69: 2026 | AA69: FALSE | AB69: <a href="https://sberauto.bitrix24.ru/crm/deal/details/506282/"target="_blank">Ссылка</a>
A70: 406 | B70: 46259 | C70: 529510 | D70: 102862 | E70: Закрыто и реализованно | F70: 501906 | G70: 5074421 | H70: ONLINE ДИАЛОГ А | I70: 1649021206 | J70: 52260 | K70: да | L70: лид | N70: 2613000 | O70: 52260 | P70: 26/08/19-49 | Q70: 46253 | R70: TENET | S70: Т7 | T70: Новое | U70: EDXFB32B6TE091320 | V70: 2613000 | W70: 52260 | X70: TENET Т7 EDXFB32B6TE091320 | Y70: Казань | Z70: 2026 | AA70: FALSE | AB70: <a href="https://sberauto.bitrix24.ru/crm/deal/details/529510/"target="_blank">Ссылка</a>
A71: 527 | B71: 46263 | C71: 527450 | D71: 97080 | E71: Закрыто и реализованно | F71: 505138 | G71: 2778792 | H71: ONLINE Автодин (ООО "АВТОДИН-КАМА") | I71: 1650129620 | J71: 90000 | K71: да | N71: 4500000 | O71: 90000 | P71: 3472 | Q71: 46263 | R71: Geely | S71: Monjaro | T71: Новое | U71: LB37852D0TS064011 | V71: 4500000 | W71: 90000 | X71: Geely Monjaro LB37852D0TS064011 | Y71: Москва | Z71: 2026 | AA71: FALSE | AB71: <a href="https://sberauto.bitrix24.ru/crm/deal/details/527450/"target="_blank">Ссылка</a>
A72: 1038 | B72: 46246 | C72: 514734 | D72: 97080 | E72: Закрыто и реализованно | F72: 497900 | G72: 4371154 | H72: ONLINE Автодин (ООО "АВТОДИН-КАМА") | I72: 1650129620 | J72: 55100 | K72: да | N72: 2755000 | O72: 55100 | P72: 3332 | Q72: 46242 | R72: BELGEE | S72: X50+ | T72: Новое | U72: Y4K8622Z9TB933027 | V72: 2755000 | W72: 55100 | X72: BELGEE X50+ Y4K8622Z9TB933027 | Y72: Москва | Z72: 2026 | AA72: FALSE | AB72: <a href="https://sberauto.bitrix24.ru/crm/deal/details/514734/"target="_blank">Ссылка</a>
A73: 484 | B73: 46258 | C73: 528186 | D73: 108224 | E73: Закрыто и реализованно | F73: 500632 | G73: 3481983 | H73: Online ГК Диалог \ ООО "Управляющая компания Диалог" | I73: 1650207558 | J73: 92600 | K73: да | N73: 4630000 | O73: 92600 | P73: 26/08/21-03 | Q73: 46255 | R73: Gac | S73: GS8 | T73: Новое | U73: LMGJU3G89T1061877 | V73: 4630000 | W73: 92600 | X73: Gac GS8 LMGJU3G89T1061877 | Y73: Набережные Челны | Z73: 2026 | AA73: FALSE | AB73: <a href="https://sberauto.bitrix24.ru/crm/deal/details/528186/"target="_blank">Ссылка</a>
A74: 1206 | B74: 46244 | C74: 510974 | D74: 108224 | E74: Закрыто и реализованно | F74: 495240 | G74: 5024076 | H74: Online ГК Диалог \ ООО "Управляющая компания Диалог" | I74: 1650207558 | J74: 112000 | K74: да | N74: 5600000 | O74: 112000 | P74: 26/08/08-03 | Q74: 46242 | R74: GAC | S74: S7 | T74: Новое | U74: LMGNC3S82T1001158 | V74: 5600000 | W74: 112000 | X74: GAC S7 LMGNC3S82T1001158 | Y74: Казань | Z74: 2026 | AA74: FALSE | AB74: <a href="https://sberauto.bitrix24.ru/crm/deal/details/510974/"target="_blank">Ссылка</a>
A75: 727 | B75: 46253 | C75: 524518 | D75: 108224 | E75: Закрыто и реализованно | F75: 502730 | G75: 5089965 | H75: Online ГК Диалог \ ООО "Управляющая компания Диалог" | I75: 1650207558 | J75: 63439.8 | K75: да | N75: 3171990 | O75: 63439.8 | P75: 26/08/19-01 | Q75: 46253 | R75: GEELY | S75: CITYRAY | T75: Новое | U75: LB3G43S99TX408062 | V75: 3171990 | W75: 63439.8 | X75: GEELY CITYRAY LB3G43S99TX408062 | Y75: Набережные Челны | Z75: 2026 | AA75: FALSE | AB75: <a href="https://sberauto.bitrix24.ru/crm/deal/details/524518/"target="_blank">Ссылка</a>
A76: 1209 | B76: 46242 | C76: 510934 | D76: 108224 | E76: Закрыто и реализованно | F76: 495196 | G76: 5023929 | H76: Online ГК Диалог \ ООО "Управляющая компания Диалог" | I76: 1650207558 | J76: 61000 | K76: да | N76: 3050000 | O76: 61000 | P76: ТТТ7103589125 | Q76: 46242 | R76: GEELY | S76: Cityray | T76: Новое | U76: LB3G43S93TX409353 | V76: 3050000 | W76: 61000 | X76: GEELY Cityray LB3G43S93TX409353 | Y76: Набережные Челны | Z76: 2026 | AA76: FALSE | AB76: <a href="https://sberauto.bitrix24.ru/crm/deal/details/510934/"target="_blank">Ссылка</a>
...

Sheet Дилеры_ИЮЛЬ
B1: client_id | C1: Название компании | D1: ИНН | E1: Цена | F1: КВ. Авто | G1: кв по реестру | H1: Комментарий | I1: Номер ДКП | J1: Дата ДКП | K1: brand | L1: model | M1: TYPE | N1: VIN | O1: Цена | P1: КВ. Авто | Q1: Время закрытия | R1: Deal_ID | S1: Contact_ID | T1: Название стадии | U1: Идентификатор компании | V1: Название товара | W1: CITY | X1: YEAR | Y1: Error | Z1: Ссылка на сделку
A2: 1308 | B2: 4321933 | C2: ONLINE CHERY Автолюкс (ООО "АВТОЛЮКС") | D2: =VLOOKUP(U2,Лист1!A:B,2,0) -> 2630048453 | E2: 3478000 | F2: 117475 | G2: =E2-F2 -> 3360525 | H2: формула | I2: ПЛ000000162 | J2: 46218 | K2: TENET | L2: T8 | M2: Новое | N2: EDEGD34B0SE049468 | O2: 3478000 | P2: 117475 | Q2: 46218 | R2: 481122 | S2: 473272 | T2: Закрыто и реализованно | U2: 82506 | V2: TENET T8 EDEGD34B0SE049468 | W2: Пятигорск | X2: 2026 | Y2: FALSE | Z2: <a href="https://sberauto.bitrix24.ru/crm/deal/details/481122/"target="_blank">Ссылка</a>
A3: 907 | B3: 4858987 | C3: ООО "ДЕБРЯНСК АВТО" ONLINE | D3: =VLOOKUP(U3,Лист1!A:B,2,0) -> 3250521481 | E3: 2214000 | F3: 67950 | G3: =E3-F3 -> 2146050 | H3: формула | I3: 178426 | J3: 46223 | K3: TENET | L3: T4L | M3: Новое | N3: EDELB31BXTE062593 | O3: 2214000 | P3: 67950 | Q3: 46223 | R3: 491010 | S3: 480036 | T3: Закрыто и реализованно | U3: 112892 | V3: Tenet T4L EDELB31BXTE062593 | W3: Брянск | X3: 2026 | Y3: FALSE | Z3: <a href="https://sberauto.bitrix24.ru/crm/deal/details/491010/"target="_blank">Ссылка</a>
A4: 1307 | B4: 4807154 | C4: ONLINE АГАТ CHERY/O&J (ООО "АВТО-КОНТИНЕНТ") | D4: =VLOOKUP(U4,Лист1!A:B,2,0) -> 3804048079 | E4: 3478000 | F4: 117475 | G4: =E4-F4 -> 3360525 | H4: формула | I4: АНТ002788 | J4: 46210 | K4: TENET | L4: T8 | M4: Новое | N4: EDXGD34B2TE888059 | O4: 3478000 | P4: 117475 | Q4: 46227 | R4: 481158 | S4: 471972 | T4: Закрыто и реализованно | U4: 101276 | V4: TENET T8 EDXGD34B2TE888059 | W4: Иркутск | X4: 2026 | Y4: FALSE | Z4: <a href="https://sberauto.bitrix24.ru/crm/deal/details/481158/"target="_blank">Ссылка</a>
A5: 218 | B5: 2252719 | C5: ООО "Кунцево Авто Трейдинг" (ООО "КУНЦЕВО АТ") Online | D5: =VLOOKUP(U5,Лист1!A:B,2,0) -> 5032271860 | E5: 2613000 | F5: 88900 | G5: =E5-F5 -> 2524100 | H5: формула | I5: CHR0000879 | J5: 46231 | K5: TENET | L5: T7 | M5: Новое | N5: EDXFB32B1TE087241 | O5: 2613000 | P5: 88900 | Q5: 46232 | R5: 501646 | S5: 485214 | T5: Закрыто и реализованно | U5: 107748 | V5: TENET T7 EDXFB32B1TE087241 | W5: Москва | X5: 2026 | Y5: FALSE | Z5: <a href="https://sberauto.bitrix24.ru/crm/deal/details/501646/"target="_blank">Ссылка</a>
A6: 1277 | B6: 4794021 | C6: ООО КУНЦЕВО АТ | D6: 5032271860 | E6: 2214000 | F6: 67950 | G6: =E6-F6 -> 2146050 | H6: формула | I6: CHR0000801 | J6: 46211 | K6: Tenet | L6: T4L | M6: Новое | N6: EDELB31B3TE071037 | O6: 2214000 | P6: 67950 | Q6: 46224 | R6: 481484 | S6: 473544 | T6: Закрыто и реализованно | U6: 112222 | V6: Tenet T4L EDELB31B3TE071037 | W6: Москва | X6: 2026 | Y6: FALSE | Z6: <a href="https://sberauto.bitrix24.ru/crm/deal/details/481484/"target="_blank">Ссылка</a>
A7: 435 | B7: 4342624 | C7: АО "РОЛЬФ" ONLINE | D7: =VLOOKUP(U7,Лист1!A:B,2,0) -> 5047254063 | E7: 2494000 | F7: 54000 | G7: =E7-F7 -> 2440000 | H7: формула | I7: ОМ028013 | J7: 46229 | K7: Jaecoo | L7: J6 | M7: Новое | N7: EDXDB21B6TG025275 | O7: 2494000 | P7: 54000 | Q7: 46231 | R7: 498382 | S7: 485510 | T7: Закрыто и реализованно | U7: 111670 | V7: Jaecoo J6 EDXDB21B6TG025275 | W7: Москва | X7: 2026 | Y7: FALSE | Z7: <a href="https://sberauto.bitrix24.ru/crm/deal/details/498382/"target="_blank">Ссылка</a>
A8: 364 | B8: 1246289 | C8: ONLINE CHERY/TENET Нижегородец (ООО "НИЖЕГОРОДЕЦ ВОСТОК") | D8: =VLOOKUP(U8,Лист1!A:B,2,0) -> 5257164835 | E8: 2613000 | F8: 88900 | G8: =E8-F8 -> 2524100 | H8: формула | I8: 0203306/02-H | J8: 46229 | K8: TENET | L8: Т7 | M8: Новое | N8: EDXFB32B1TE084310 | O8: 2613000 | P8: 88900 | Q8: 46230 | R8: 499656 | S8: 481266 | T8: Закрыто и реализованно | U8: 89154 | V8: Tenet T7 EDXFB32B1TE084310 | W8: Нижний Новгород | X8: 2026 | Y8: FALSE | Z8: <a href="https://sberauto.bitrix24.ru/crm/deal/details/499656/"target="_blank">Ссылка</a>
A9: 1377 | B9: 4803511 | C9: ONLINE CHERY/TENET Нижегородец (ООО "НИЖЕГОРОДЕЦ ВОСТОК") | D9: =VLOOKUP(U9,Лист1!A:B,2,0) -> 5257164835 | E9: 2529000 | F9: 88800 | G9: =E9-F9 -> 2440200 | H9: формула | I9: 0199321/02-H | J9: 46207 | K9: TENET | L9: T7 | M9: Новое | N9: EDXFD32B2TE039726 | O9: 2529000 | P9: 88800 | Q9: 46208 | R9: 478854 | S9: 471466 | T9: Закрыто и реализованно | U9: 89154 | V9: TENET T7 EDXFD32B2TE039726 | W9: Нижний Новгород | X9: 2026 | Y9: FALSE | Z9: <a href="https://sberauto.bitrix24.ru/crm/deal/details/478854/"target="_blank">Ссылка</a>
A10: 1009 | B10: 4615723 | C10: ONLINE ЛунаАвто (ООО "ЛУНААВТО") | D10: =VLOOKUP(U10,Лист1!A:B,2,0) -> 5410065297 | E10: 2906000 | F10: 94200 | G10: =E10-F10 -> 2811800 | H10: формула | I10: 00000000926 | J10: 46221 | K10: Tenet | L10: T7 | M10: Новое | N10: EDXFD32B5TE080142 | O10: 2906000 | P10: 94200 | Q10: 46223 | R10: 488416 | S10: 478080 | T10: Закрыто и реализованно | U10: 75574 | V10: Tenet T7 EDXFD32B5TE080142 | W10: Новосибирск | X10: 2026 | Y10: FALSE | Z10: <a href="https://sberauto.bitrix24.ru/crm/deal/details/488416/"target="_blank">Ссылка</a>
A11: 1246 | B11: 4823955 | C11: ONLINE ЧЕРИ ЦЕНТР ТЕМП АВТО ДОН (ООО "ТЕМП АВТО ДОН") | D11: =VLOOKUP(U11,Лист1!A:B,2,0) -> 6155046305 | E11: 2549010 | F11: 88800 | G11: =E11-F11 -> 2460210 | H11: формула | I11: 11181 | J11: 46215 | K11: Tenet | L11: T7 | M11: Новое | N11: EDXFD32B7TE046803 | O11: 2549010 | P11: 88800 | Q11: 46217 | R11: 482572 | S11: 474326 | T11: Закрыто и реализованно | U11: 75462 | V11: Tenet T7 EDXFD32B7TE046803 | W11: Ростов-На-Дону | X11: 2026 | Y11: FALSE | Z11: <a href="https://sberauto.bitrix24.ru/crm/deal/details/482572/"target="_blank">Ссылка</a>
A12: 1258 | B12: 4565354 | C12: ONLINE CHERY Автофорум (ООО "АВТОФОРУМ ЦЕНТР") | D12: =VLOOKUP(U12,Лист1!A:B,2,0) -> 6452947574 | E12: 2529000 | F12: 88800 | G12: =E12-F12 -> 2440200 | H12: формула | I12: 000001026 | J12: 46212 | K12: TENET | L12: T7 | M12: Новое | N12: EDXFD32B0TE043306 | O12: 2529000 | P12: 88800 | Q12: 46213 | R12: 482312 | S12: 474156 | T12: Закрыто и реализованно | U12: 93280 | V12: TENET T7 EDXFD32B0TE043306 | W12: Саратов | X12: 2026 | Y12: FALSE | Z12: <a href="https://sberauto.bitrix24.ru/crm/deal/details/482312/"target="_blank">Ссылка</a>
A13: 813 | B13: 4836243 | C13: ONLINE ЧЕРИ ЦЕНТР ПЛАНЕТА АВТО ВОСТОК (ООО "АВТОГАРАНТИЯ") | D13: =VLOOKUP(U13,Лист1!A:B,2,0) -> 7447124619 | E13: 2529000 | F13: 88800 | G13: =E13-F13 -> 2440200 | H13: формула | I13: 1523 F/T | J13: 46197 | K13: Tenet | L13: T7 | M13: Новое | N13: EDXFD32B9TE047211 | O13: 2529000 | P13: 88800 | Q13: 46234 | R13: 494018 | S13: 476864 | T13: Закрыто и реализованно | U13: 101774 | V13: Tenet T7 EDXFD32B9TE047211 | W13: Челябинск | X13: 2026 | Y13: FALSE | Z13: <a href="https://sberauto.bitrix24.ru/crm/deal/details/494018/"target="_blank">Ссылка</a>
A14: 1352 | B14: 4477163 | C14: ONLINE ЧЕРИ ЦЕНТР ПЛАНЕТА АВТО ВОСТОК (ООО "АВТОГАРАНТИЯ") | D14: =VLOOKUP(U14,Лист1!A:B,2,0) -> 7447124619 | E14: 2855600 | F14: 94200 | G14: =E14-F14 -> 2761400 | H14: формула | I14: 1647 F/T | J14: 46212 | K14: Tenet | L14: T7 | M14: Новое | N14: EDXFD32BXTE079357 | O14: 2855600 | P14: 94200 | Q14: 46217 | R14: 479664 | S14: 472268 | T14: Закрыто и реализованно | U14: 101774 | V14: Tenet T7 EDXFD32BXTE079357 | W14: Челябинск | X14: 2026 | Y14: FALSE | Z14: <a href="https://sberauto.bitrix24.ru/crm/deal/details/479664/"target="_blank">Ссылка</a>
A15: 1263 | B15: 4815867 | C15: ООО "СИГМА АВТО" | D15: =VLOOKUP(U15,Лист1!A:B,2,0) -> 7813649997 | E15: 3078000 | F15: 105000 | G15: =E15-F15 -> 2973000 | H15: формула | I15: САЗА-015082 | J15: 46212 | K15: OMODA | L15: C7 | M15: Новое | N15: EDEKD32B6TE055676 | O15: 3078000 | P15: 105000 | Q15: 46223 | R15: 482022 | S15: 481592 | T15: Закрыто и реализованно | U15: 80978 | V15: OMODA C7 EDEKD32B6TE055676 | W15: Санкт-Петербург | X15: 2026 | Y15: FALSE | Z15: <a href="https://sberauto.bitrix24.ru/crm/deal/details/482022/"target="_blank">Ссылка</a>
A16: 208 | B16: 4917519 | C16: ООО "МС МОТОРС ЗУБОВО" ONLINE | D16: =VLOOKUP(U16,Лист1!A:B,2,0) -> 245961925 | E16: 2270000 | F16: 45400 | I16: 26/07-34/ам | J16: 46228 | K16: Jetour | L16: X70+ | M16: Новое | N16: EC37LUSM8TC005444 | O16: 2270000 | P16: 45400 | Q16: 46233 | R16: 502032 | S16: 488282 | T16: Закрыто и реализованно | U16: 113078 | V16: Jetour X70+ EC37LUSM8TC005444 | W16: РЕСПУБЛИКА БАШКОРТОСТАН УФИМСКИЙ С. ЗУБОВО | X16: 2026 | Y16: FALSE | Z16: <a href="https://sberauto.bitrix24.ru/crm/deal/details/502032/"target="_blank">Ссылка</a>
A17: 216 | B17: 4894679 | C17: ООО "МС МОТОРС ЗУБОВО" ONLINE | D17: =VLOOKUP(U17,Лист1!A:B,2,0) -> 245961925 | E17: 3708900 | F17: 74178 | I17: 26/07-30/АМ | J17: 46226 | K17: Jetour | L17: Т2 | M17: Новое | N17: EC3TEUMB0T0003922 | O17: 3708900 | P17: 74178 | Q17: 46232 | R17: 501674 | S17: 487974 | T17: Закрыто и реализованно | U17: 113078 | V17: Jetour Т2 EC3TEUMB0T0003922 | W17: Уфа | X17: 2026 | Y17: FALSE | Z17: <a href="https://sberauto.bitrix24.ru/crm/deal/details/501674/"target="_blank">Ссылка</a>
A18: 1006 | B18: 4856024 | C18: ООО "МС МОТОРС ЗУБОВО" ONLINE | D18: =VLOOKUP(U18,Лист1!A:B,2,0) -> 245961925 | E18: 3660000 | F18: 73200 | I18: 26/07-33/АМ | J18: 46227 | K18: JETOUR | L18: T2 | M18: Новое | N18: EC3TEUMB0T0002818 | O18: 3660000 | P18: 73200 | Q18: 46233 | R18: 488530 | S18: 478436 | T18: Закрыто и реализованно | U18: 113078 | V18: JETOUR T2 EC3TEUMB0T0002818 | W18: Зубово | X18: 2026 | Y18: FALSE | Z18: <a href="https://sberauto.bitrix24.ru/crm/deal/details/488530/"target="_blank">Ссылка</a>
A19: 1079 | B19: 3395055 | C19: Online ООО Автосеть Уфа | D19: =VLOOKUP(U19,Лист1!A:B,2,0) -> 276945049 | E19: 2733000 | F19: 40995 | H19: стандарт отчет | I19: УФ000001709 | J19: 46224 | K19: TENET | L19: Т7 | M19: Новое | N19: EDXFB32B8TE087186 | O19: 2733000 | P19: 40995 | Q19: 46227 | R19: 487416 | S19: 477370 | T19: Закрыто и реализованно | U19: 86024 | V19: Tenet T7 EDXFB32B8TE087186 | W19: Уфа | X19: 2026 | Y19: FALSE | Z19: <a href="https://sberauto.bitrix24.ru/crm/deal/details/487416/"target="_blank">Ссылка</a>
A20: 19 | B20: 2744728 | C20: Прагматика (ПЕТРОЗАВОДСК-ЛАДА) | D20: =VLOOKUP(U20,Лист1!A:B,2,0) -> 1001340114 | E20: 1930000 | F20: 19300 | I20: 31-11024446-КП | J20: 46234 | K20: LADA | L20: Niva | M20: Новое | N20: XTA212310T1000785 | O20: 1930000 | P20: 19300 | Q20: 46234 | R20: 505410 | S20: 448486 | T20: Закрыто и реализованно | U20: 95208 | V20: LADA Niva XTA212310T1000785 | W20: Москва | X20: 2026 | Y20: FALSE | Z20: <a href="https://sberauto.bitrix24.ru/crm/deal/details/505410/"target="_blank">Ссылка</a>
A21: 25 | B21: 4851281 | C21: Online ООО "ЛЕОН" | D21: =VLOOKUP(U21,Лист1!A:B,2,0) -> 1207901941 | E21: 3974000 | F21: 79480 | I21: ДТ-43 | J21: 46233 | K21: JETOUR | L21: Т1 | M21: Новое | N21: LVTDD24B7TDC00840 | O21: 3974000 | P21: 79480 | Q21: 46234 | R21: 505338 | S21: 485970 | T21: Закрыто и реализованно | U21: 112880 | V21: JETOUR Т1 LVTDD24B7TDC00840 | W21: Медведево | X21: 2026 | Y21: FALSE | Z21: <a href="https://sberauto.bitrix24.ru/crm/deal/details/505338/"target="_blank">Ссылка</a>
A22: 961 | B22: 4861970 | C22: Online ООО "ЛЕОН" | D22: =VLOOKUP(U22,Лист1!A:B,2,0) -> 1207901941 | E22: 2270000 | F22: 45400 | H22: не наш клиент отмена кв | I22: ДТ-38 | J22: 46219 | K22: Jetour | L22: X70+ | M22: Новое | N22: EC37LUSM5TC004994 | O22: 2270000 | P22: 45400 | Q22: 46219 | R22: 489484 | S22: 479090 | T22: Закрыто и реализованно | U22: 112880 | V22: Jetour X70+ EC37LUSM5TC004994 | W22: Йошкар-Ола | X22: 2026 | Y22: FALSE | Z22: <a href="https://sberauto.bitrix24.ru/crm/deal/details/489484/"target="_blank">Ссылка</a>
A23: 1322 | B23: 4814824 | C23: ООО "КОНДОР-ПЛЮС" ONLINE | D23: =VLOOKUP(U23,Лист1!A:B,2,0) -> 1215185868 | E23: 2244000 | F23: 44880 | I23: 21-26-О | J23: 46210 | K23: Jetour | L23: X70+ | M23: Новое | N23: EC37LUSM7SC003439 | O23: 2244000 | P23: 44880 | Q23: 46210 | R23: 480494 | S23: 472842 | T23: Закрыто и реализованно | U23: 112548 | V23: Jetour X70+ EC37LUSM7SC003439 | W23: Йошкар - Ола | X23: 2025 | Y23: FALSE | Z23: <a href="https://sberauto.bitrix24.ru/crm/deal/details/480494/"target="_blank">Ссылка</a>
A24: 607 | B24: 4911640 | C24: ООО "КМ-АВТО САРАНСК-2" ONLINE | D24: =VLOOKUP(U24,Лист1!A:B,2,0) -> 1300005883 | E24: 2900000 | F24: 58000 | I24: М000000066 | J24: 46227 | K24: SOLARIS | L24: HC | M24: Новое | N24: Z94PF814BSR072863 | O24: 2900000 | P24: 58000 | Q24: 46234 | R24: 496762 | S24: 484190 | T24: Закрыто и реализованно | U24: 111882 | V24: SOLARIS HC Z94PF814BSR072863 | X24: 2025 | Y24: TRUE | Z24: <a href="https://sberauto.bitrix24.ru/crm/deal/details/496762/"target="_blank">Ссылка</a>
A25: 769 | B25: 4631928 | C25: ООО "КМ-АВТО САРАНСК-2" ONLINE | D25: =VLOOKUP(U25,Лист1!A:B,2,0) -> 1300005883 | E25: 3303000 | F25: 66060 | I25: М000000065 | J25: 46218 | K25: SOLARIS | L25: HC | M25: Новое | N25: Z94PC815DSR069291 | O25: 3303000 | P25: 66060 | Q25: 46234 | R25: 494746 | S25: 482770 | T25: Закрыто и реализованно | U25: 111882 | V25: SOLARIS HC Z94PC815DSR069291 | W25: Саранск | X25: 2025 | Y25: FALSE | Z25: <a href="https://sberauto.bitrix24.ru/crm/deal/details/494746/"target="_blank">Ссылка</a>
A26: 929 | B26: 4874758 | C26: ООО "КМ-АВТО САРАНСК-2" ONLINE | D26: =VLOOKUP(U26,Лист1!A:B,2,0) -> 1300005883 | E26: 2772000 | F26: 55440 | I26: М000000064 | J26: 46221 | K26: Solaris | L26: HC | M26: Новое | N26: Z94PB814BSR071971 | O26: 2772000 | P26: 55440 | Q26: 46223 | R26: 490046 | S26: 479520 | T26: Закрыто и реализованно | U26: 111882 | V26: Solaris HC Z94PB814BSR071971 | W26: Саранск | X26: 2025 | Y26: FALSE | Z26: <a href="https://sberauto.bitrix24.ru/crm/deal/details/490046/"target="_blank">Ссылка</a>
A27: 994 | B27: 4866202 | C27: ООО "КМ-АВТО САРАНСК-2" ONLINE | D27: =VLOOKUP(U27,Лист1!A:B,2,0) -> 1300005883 | E27: 2350000 | F27: 47000 | I27: М0000000б3 | J27: 46218 | K27: SOLARIS | L27: KRS | M27: Новое | N27: Z94C241BBSR272703 | O27: 2350000 | P27: 47000 | Q27: 46218 | R27: 488710 | S27: 478606 | T27: Закрыто и реализованно | U27: 111882 | V27: SOLARIS KRS Z94C241BBSR272703 | W27: Саранск | X27: 2025 | Y27: FALSE | Z27: <a href="https://sberauto.bitrix24.ru/crm/deal/details/488710/"target="_blank">Ссылка</a>
A28: 1362 | B28: 4808170 | C28: ООО "КМ-АВТО САРАНСК-2" ONLINE | D28: =VLOOKUP(U28,Лист1!A:B,2,0) -> 1300005883 | E28: 3235000 | F28: 64700 | I28: М000000060 | J28: 46206 | K28: SOLARIS | L28: HC | M28: Новое | N28: Z94PC815BSR071911 | O28: 3235000 | P28: 64700 | Q28: 46234 | R28: 478996 | S28: 471766 | T28: Закрыто и реализованно | U28: 111882 | V28: SOLARIS HC Z94PC815BSR071911 | W28: Саранск | X28: 2025 | Y28: FALSE | Z28: <a href="https://sberauto.bitrix24.ru/crm/deal/details/478996/"target="_blank">Ссылка</a>
A29: 1404 | B29: 4804089 | C29: ООО "КМ-АВТО САРАНСК-2" ONLINE | D29: =VLOOKUP(U29,Лист1!A:B,2,0) -> 1300005883 | E29: 3235000 | F29: 64700 | H29: дубль сделки (закрыта дважды на мужа и жену) | I29: М000000060 | J29: 46206 | K29: SOLARIS | L29: HC | M29: Новое | N29: Z94PC815BSR071911 | O29: 3235000 | P29: 64700 | Q29: 46212 | R29: 478190 | S29: 471102 | T29: Закрыто и реализованно | U29: 111882 | V29: SOLARIS HC Z94PC815BSR071911 | W29: Саранск | X29: 2025 | Y29: FALSE | Z29: <a href="https://sberauto.bitrix24.ru/crm/deal/details/478190/"target="_blank">Ссылка</a>
A30: 842 | B30: 4889422 | C30: ООО "АРМАДА-АВТО" online | D30: =VLOOKUP(U30,Лист1!A:B,2,0) -> 1615009225 | E30: 3253750 | F30: 65075 | I30: АА00000810 | J30: 46232 | K30: Solaris | L30: HC | M30: Новое | N30: Z94PC815DSR072244 | O30: 3253750 | P30: 65075 | Q30: 46232 | R30: 493752 | S30: 482058 | T30: Закрыто и реализованно | U30: 112710 | V30: Solaris HC Z94PC815DSR072244 | W30: Нижнекамск | X30: 2025 | Y30: FALSE | Z30: <a href="https://sberauto.bitrix24.ru/crm/deal/details/493752/"target="_blank">Ссылка</a>
A31: 939 | B31: 4865992 | C31: ООО "АРМАДА-АВТО" online | D31: =VLOOKUP(U31,Лист1!A:B,2,0) -> 1615009225 | E31: 2290000 | F31: 45800 | I31: 685/2026 | J31: 46229 | K31: Jetour | L31: X70+ | M31: Новое | N31: EC37LUSM6TC006253 | O31: 2290000 | P31: 45800 | Q31: 46230 | R31: 489806 | S31: 479352 | T31: Закрыто и реализованно | U31: 112710 | V31: Jetour X70+ EC37LUSM6TC006253 | W31: Екатеринбург | X31: 2026 | Y31: FALSE | Z31: <a href="https://sberauto.bitrix24.ru/crm/deal/details/489806/"target="_blank">Ссылка</a>
A32: 940 | B32: 485637 | C32: ООО "АРМАДА-АВТО" online | D32: =VLOOKUP(U32,Лист1!A:B,2,0) -> 1615009225 | E32: 2290000 | F32: 45800 | I32: 663/2026 | J32: 46224 | K32: Jetour | L32: Х70+ | M32: Новое | N32: EC37LUSM4TC005344 | O32: 2290000 | P32: 45800 | Q32: 46227 | R32: 489800 | S32: 479338 | T32: Закрыто и реализованно | U32: 112710 | V32: Jetour Х70+ EC37LUSM4TC005344 | W32: Екатеренбург | X32: 2026 | Y32: FALSE | Z32: <a href="https://sberauto.bitrix24.ru/crm/deal/details/489800/"target="_blank">Ссылка</a>
A33: 1366 | B33: 4761427 | C33: ООО "АРМАДА-АВТО" online | D33: =VLOOKUP(U33,Лист1!A:B,2,0) -> 1615009225 | E33: 2270000 | F33: 45400 | I33: АА00000735 | J33: 46212 | K33: JETOUR | L33: X70+ | M33: Новое | N33: EC37LUSMXSC003595 | O33: 2270000 | P33: 45400 | Q33: 46233 | R33: 478958 | S33: 471736 | T33: Закрыто и реализованно | U33: 112710 | V33: Jetour X70+ EC37LUSMXSC003595 | W33: Нижнекамск | X33: 2026 | Y33: FALSE | Z33: <a href="https://sberauto.bitrix24.ru/crm/deal/details/478958/"target="_blank">Ссылка</a>
A34: 197 | B34: 4951688 | C34: ONLINE ООО "ДИАЛОГ АВТО" | D34: =VLOOKUP(U34,Лист1!A:B,2,0) -> 1644062657 | E34: 2300000 | F34: 46000 | I34: 29/07/26-11 | J34: 46232 | K34: JETOUR | L34: X70+ | M34: Новое | N34: EC37LUSM4TC006557 | O34: 2300000 | P34: 46000 | Q34: 46233 | R34: 502136 | S34: 488358 | T34: Закрыто и реализованно | U34: 107326 | V34: JETOUR X70PLUS EC37LUSM4TC006557 | X34: 2026 | Y34: TRUE | Z34: <a href="https://sberauto.bitrix24.ru/crm/deal/details/502136/"target="_blank">Ссылка</a>
A35: 382 | B35: 4935425 | C35: ONLINE ООО "ДИАЛОГ АВТО" | D35: =VLOOKUP(U35,Лист1!A:B,2,0) -> 1644062657 | E35: 2230000 | F35: 44600 | I35: 26/07/27-01 | J35: 46230 | K35: JETOUR | L35: X70+ | M35: Новое | N35: EC37CUSMXTC005963 | O35: 2230000 | P35: 44600 | Q35: 46231 | R35: 499414 | S35: 486346 | T35: Закрыто и реализованно | U35: 107326 | V35: JETOUR X70+ EC37CUSMXTC005963 | X35: 2026 | Y35: TRUE | Z35: <a href="https://sberauto.bitrix24.ru/crm/deal/details/499414/"target="_blank">Ссылка</a>
A36: 426 | B36: 4929653 | C36: ONLINE ООО "ДИАЛОГ АВТО" | D36: =VLOOKUP(U36,Лист1!A:B,2,0) -> 1644062657 | E36: 3385000 | F36: 67700 | I36: 26/07/26-01 | J36: 46229 | K36: SOLARIS | L36: HC | M36: Новое | N36: Z94PC815DSR052827 | O36: 3385000 | P36: 67700 | Q36: 46230 | R36: 498478 | S36: 485592 | T36: Закрыто и реализованно | U36: 107326 | V36: SOLARIS HC Z94PC815DSR052827 | W36: Казань | X36: 2025 | Y36: FALSE | Z36: <a href="https://sberauto.bitrix24.ru/crm/deal/details/498478/"target="_blank">Ссылка</a>
A37: 533 | B37: 4923711 | C37: ONLINE ООО "ДИАЛОГ АВТО" | D37: =VLOOKUP(U37,Лист1!A:B,2,0) -> 1644062657 | E37: 2040000 | F37: 40800 | I37: TTT7091172177 | J37: 46228 | K37: JETOUR | L37: DASHING | M37: Новое | N37: EC3DCUFD7TC010521 | O37: 2040000 | P37: 40800 | Q37: 46233 | R37: 497420 | S37: 484704 | T37: Закрыто и реализованно | U37: 107326 | V37: JETOUR DASHING EC3DCUFD7TC010521 | W37: Казань | X37: 2026 | Y37: FALSE | Z37: <a href="https://sberauto.bitrix24.ru/crm/deal/details/497420/"target="_blank">Ссылка</a>
A38: 557 | B38: 4920996 | C38: ONLINE ООО "ДИАЛОГ АВТО" | D38: =VLOOKUP(U38,Лист1!A:B,2,0) -> 1644062657 | E38: 2040000 | F38: 40800 | I38: 26/07/24-01 | J38: 46227 | K38: JETOUR | L38: DASHING | M38: Новое | N38: EC3DCUFD7TC011037 | O38: 2040000 | P38: 40800 | Q38: 46231 | R38: 497034 | S38: 484412 | T38: Закрыто и реализованно | U38: 107326 | V38: JETOUR DASHING EC3DCUFD7TC011037 | W38: Казань | X38: 2026 | Y38: FALSE | Z38: <a href="https://sberauto.bitrix24.ru/crm/deal/details/497034/"target="_blank">Ссылка</a>
A39: 559 | B39: 4920882 | C39: ONLINE ООО "ДИАЛОГ АВТО" | D39: =VLOOKUP(U39,Лист1!A:B,2,0) -> 1644062657 | E39: 2070000 | F39: 41400 | I39: 26/07/24-11 | J39: 46227 | K39: JETOUR | L39: DASHING | M39: Новое | N39: EC3DCUFD6TC010784 | O39: 2070000 | P39: 41400 | Q39: 46231 | R39: 497014 | S39: 484396 | T39: Закрыто и реализованно | U39: 107326 | V39: JETOUR DASHING EC3DCUFD6TC010784 | W39: Казань | X39: 2026 | Y39: FALSE | Z39: <a href="https://sberauto.bitrix24.ru/crm/deal/details/497014/"target="_blank">Ссылка</a>
A40: 771 | B40: 452010 | C40: ONLINE ГК Диалог \ ООО Диалог Авто | D40: =VLOOKUP(U40,Лист1!A:B,2,0) -> 1644062657 | E40: 1970000 | F40: 39400 | I40: 26/07/21-01 | J40: 46224 | K40: Jetour | L40: Dashing | M40: Новое | N40: EC3DCUFD6TC010557 | O40: 1970000 | P40: 39400 | Q40: 46226 | R40: 494736 | S40: 482758 | T40: Закрыто и реализованно | U40: 108228 | V40: Jetour Dashing EC3DCUFD6TC010557 | W40: Набережные челны | X40: 2026 | Y40: FALSE | Z40: <a href="https://sberauto.bitrix24.ru/crm/deal/details/494736/"target="_blank">Ссылка</a>
...

Sheet Лист1
A1: ID | B1: Реквизит (Россия): ИНН
A2: 113168 | B2: 5257188836
A4: 113166
A5: 113164
A6: 113162
A7: 113160 | B7: 7810684545
A8: 113158 | B8: 5001048893
A10: 113156 | B10: 5001048893
A12: 113154
A13: 113152
A14: 113150
A15: 113148
A16: 113146 | B16: 276971419
A17: 113144
A18: 113142
A19: 113140
A20: 113138 | B20: 3664048710
A21: 113134
A22: 113132
A23: 113130 | B23: 7804540104
A24: 113128 | B24: 7729520988
A25: 113126
A26: 113124
A27: 113122
A28: 113120
A29: 113118 | B29: 5403342038
A31: 113116 | B31: 6732074435
A32: 113114 | B32: 7814721879
A33: 113112
A34: 113110 | B34: 7730653453
A35: 113108
A36: 113106 | B36: 7814824190
A37: 113104
A38: 113102
A39: 113100
A40: 113098
A41: 113096
A42: 113094
A43: 113092
A44: 113090 | B44: 7814367593
...
